Workbook

Sheet Review
A1: GOLDEN EVALUATION BENCHMARK — ASSISTED HUMAN REVIEW WORKBOOK
A2: Total Messages: | B2: 200 | C2: Pending Review: | D2: =COUNTBLANK(D6:D205) | E2: Completed Review: | F2: =COUNTA(D6:D205) | G2: Completion %: | H2: =COUNTA(D6:D205)/200
A3: INSTRUCTIONS: Candidate columns (Soft Blue) provide machine proposals to accelerate review. Fill green columns (D, F, H, J, L, N) for human gold labels. Do NOT modify original text or IDs.
A5: message_id | B5: original_text | C5: assistant_proposed_intent | D5: my_final_intent | E5: assistant_proposed_language | F5: my_final_language | G5: assistant_proposed_conversation_state | H5: my_final_conversation_state | I5: assistant_proposed_escalate | J5: my_final_escalate | K5: assistant_proposed_is_security_alert | L5: my_final_is_security_alert | M5: assistant_proposed_priority | N5: my_final_priority | O5: assistant_proposed_reason | P5: assistant_confidence | Q5: assistant_ambiguity_note | R5: notes
A6: 1721 | B6: @AmazonHelp Never got the beta and now I’m being told I won’t get ANY of the other stuff. Including Last Jedi content and or bonus classes. Anything! :( | C6: General / Feedback / Other | E6: en | G6: active_troubleshooting | I6: true | K6: false | M6: standard | O6: Complaint regarding game pre-order beta codes and promotional content. | P6: MEDIUM | Q6: Could resemble Order & Checkout or Digital Services & Devices, but focuses on promotional extras.
A7: 25279 | B7: @AmazonHelp Yes I have contacted Amazon and this problem is going to cost me a lot of money and as of right now there is solution. | C7: General / Feedback / Other | E7: en | G7: active_troubleshooting | I7: true | K7: false | M7: standard | O7: Customer stating that previous contact did not resolve an expensive ongoing issue. | P7: MEDIUM | Q7: Could relate to multiple domains, but tweet contains no specific operational facts.
A8: 34485 | B8: @AmazonHelp Bonjour et merci. Un vendeur tiers qui ne répond pas et qui après enquête a tout l'air d'être un escroc. | C8: Seller & Product Quality | E8: fr | G8: active_troubleshooting | I8: true | K8: false | M8: standard | O8: Customer reporting non-responsive third-party marketplace seller who appears to be an escrow scammer. | P8: HIGH | Q8: Could resemble Account Access & Security due to 'escroc' (scam), but problem is 3rd-party merchant conduct.
A9: 49143 | B9: @AmazonHelp Yes but it is a robot emails! I tried and mailed several emails with my bank statement and nothing happens. Hv other email for help me? | C9: Payment, Billing & Gift Cards | E9: en | G9: active_troubleshooting | I9: true | K9: false | M9: standard | O9: Customer emailed bank statements to verify payment but received automated unhelpful responses. | P9: HIGH | Q9: Could resemble Account Access & Security if bank statement is for ID verification, but involves payment proof.
A10: 57428 | B10: @AmazonHelp It say's "Could not set your address. Please ensure you have correctly entered a complete address" when I am entering my India address | C10: General / Feedback / Other | E10: en | G10: active_troubleshooting | I10: false | K10: false | M10: standard | O10: Address input validation error when entering India shipping address. | P10: MEDIUM | Q10: Could resemble Order & Checkout, but represents address book entry error.
A11: 61025 | B11: So I change my country of residence &amp; I get charged again for prime services without mentioning that before?! #NotCool #UX 🤬 @116316 | C11: Prime & Subscription Services | E11: en | G11: new_issue | I11: true | K11: false | M11: standard | O11: Customer charged duplicate Prime membership fee upon changing country of residence without advance disclosure. | P11: HIGH | Q11: Could resemble Payment, Billing & Gift Cards due to unexpected charge, but contract issue is Prime subscription transfer.
A12: 65900 | B12: @119625 plzzz check DM | C12: General / Feedback / Other | E12: en | G12: dm_handoff | I12: false | K12: false | M12: standard | O12: Customer stating that details have been sent via Direct Message; conversational handshake. | P12: HIGH
A13: 77408 | B13: @AmazonHelp Please don't buy any product from amazon , if all thing is smooth you don't feel anytging, but if a problem happened then you see real face of so called customer centric company amazon | C13: General / Feedback / Other | E13: en | G13: active_troubleshooting | I13: false | K13: false | M13: standard | O13: Non-transactional social communication, conversational follow-up, or general inquiry. | P13: HIGH
A14: 77535 | B14: @AmazonHelp It must be. I've had the same email address for years and I have tons of old order confirmations in my inbox. | C14: General / Feedback / Other | E14: en | G14: active_troubleshooting | I14: false | K14: false | M14: standard | O14: Non-transactional social communication, conversational follow-up, or general inquiry. | P14: HIGH
A15: 83454 | B15: Pedido en @116928 este lunes (cybermonday) Esta mañana en el tracking me pone que se ha retrasado... Llega hoy. Bien @116928 Así sí | C15: General / Feedback / Other | E15: es | G15: new_issue | I15: false | K15: false | M15: standard | O15: Non-transactional social communication, conversational follow-up, or general inquiry. | P15: HIGH
A16: 86157 | B16: @115850 @AmazonHelp do you take any action when delivery boy falsely claims that he attempted delivery | C16: Delivery Problem & Logistics | E16: en | G16: new_issue | I16: true | K16: false | M16: standard | O16: Delivery carrier falsely recorded a delivery attempt without visiting customer location. | P16: HIGH
A17: 95437 | B17: @AmazonHelp - It is really poor service or has your online chat support been hacked ? | C17: Account Access & Security | E17: en | G17: new_issue | I17: true | K17: false | M17: standard | O17: Customer inquiring whether support chat has been hacked due to bizarre or degraded service experience. | P17: MEDIUM | Q17: Could resemble General / Feedback / Other due to sarcastic frustration, but explicit inquiry about hacked chat warrants security review.
A18: 105253 | B18: @AmazonHelp Ich hatte vergessen zu erwähnen, dass es ein englisches ebook ist. Wie sieht es da mit der Vorbestellergarantie aus? | C18: Digital Services & Devices | E18: de | G18: active_troubleshooting | I18: false | K18: false | M18: standard | O18: Inquiry regarding pre-order price guarantee applicability to an English digital eBook. | P18: MEDIUM | Q18: Could resemble Order & Checkout due to pre-order guarantee, but digital eBook format specifics apply.
A19: 108116 | B19: @140000 @AmazonHelp Buenos días, lamentamos lo sucedido. Os ponemos en contacto con @132703 para que os puedan ayudar a solucionarlo lo antes posible. Muchas gracias | C19: General / Feedback / Other | E19: es | G19: active_troubleshooting | I19: false | K19: false | M19: standard | O19: Non-transactional social communication, conversational follow-up, or general inquiry. | P19: HIGH
A20: 122029 | B20: O verdadeiro significado da expressão ENTREGA RÁPIDA @117086 @6926 🤓 https://t.co/Y56yLOULEv | C20: General / Feedback / Other | E20: pt | G20: new_issue | I20: false | K20: false | M20: standard | O20: Non-transactional social communication, conversational follow-up, or general inquiry. | P20: HIGH
A21: 137150 | B21: @AmazonHelp I’ve looked in there and there is no option for that, I’ve had items delivered before at the weekend | C21: General / Feedback / Other | E21: en | G21: active_troubleshooting | I21: false | K21: false | M21: standard | O21: Non-transactional social communication, conversational follow-up, or general inquiry. | P21: HIGH
A22: 139986 | B22: Sympa, quand tu commande une Yankee candle sur @120533 et qu'elle arrive en mille morceaux 😠 | C22: Delivery Problem & Logistics | E22: fr | G22: new_issue | I22: true | K22: false | M22: standard | O22: Fragile Yankee candle arrived shattered in a thousand pieces due to courier shipping handling. | P22: HIGH | Q22: Could resemble Seller & Product Quality, but shatter damage during transit is a delivery logistics failure.
A23: 140066 | B23: @AmazonHelp Voici : C20025897313 Parceque j'ai beau me plaindre à chaque fois (genre colis ouvert pour rentrer les articles 1 par 1 dans ma BaL), vous m'expediez de + en + par Amz Logistics et ça ne va pas mieux. Je vais bien finir par vous quitter hein… | C23: Delivery Problem & Logistics | E23: fr | G23: follow_up | I23: true | K23: false | M23: standard | O23: Recurring courier mishandling with packages opened and shoved into mailbox by Amazon Logistics. | P23: HIGH
A24: 142048 | B24: @AmazonHelp hey, on another note, two of my recent purchases which i asked for a return, havent been picked up yet. it's been more than two weeks. | C24: Returns, Replacements & Refunds | E24: en | G24: active_troubleshooting | I24: true | K24: false | M24: standard | O24: Return courier has failed to pick up two returned items for over two weeks. | P24: HIGH | Q24: Could resemble Delivery Problem & Logistics due to courier delay, but operation is return reverse-logistics.
A25: 142870 | B25: @AmazonHelp Tell you what I will ask is how come prime is no longer next day delivery? I’ve ordered loads of things lately over the last month and they’ve taken ages to be delivered? | C25: Delivery Problem & Logistics | E25: en | G25: active_troubleshooting | I25: true | K25: false | M25: standard | O25: Orders taking weeks despite customer paying for Prime guaranteed next-day delivery. | P25: HIGH | Q25: Mentions Prime, but under taxonomy rules late delivery complaints belong to Delivery Problem & Logistics.
A26: 162100 | B26: @AmazonHelp Ja. Komm nicht an der Info vorbei. Bei einem anderen Spiel lief es problemlos | C26: Digital Services & Devices | E26: de | G26: active_troubleshooting | I26: false | K26: false | M26: standard | O26: Customer unable to proceed past information screen in a digital gaming title where another game worked fine. | P26: HIGH | Q26: Could resemble Order & Checkout as software purchase, but is an in-game technical bug.
A27: 167890 | B27: Hoje de manhã comprei 7 livros na @117086 e já recebi email falando que foi enviado. ♡ | C27: General / Feedback / Other | E27: pt | G27: new_issue | I27: false | K27: false | M27: standard | O27: Non-transactional social communication, conversational follow-up, or general inquiry. | P27: HIGH
A28: 179265 | B28: @AmazonHelp En espérant cette fois avoir une réponse pertinente... | C28: General / Feedback / Other | E28: fr | G28: active_troubleshooting | I28: false | K28: false | M28: standard | O28: Non-transactional social communication, conversational follow-up, or general inquiry. | P28: HIGH
A29: 180800 | B29: @AmazonHelp No worries I've asked mr Jeff @115851 to do that Jeff here is the URL https://t.co/4wKCSmoFTW?amp=1 | C29: General / Feedback / Other | E29: en | G29: follow_up | I29: false | K29: false | M29: standard | O29: Non-transactional social communication, conversational follow-up, or general inquiry. | P29: HIGH
A30: 183483 | B30: @AmazonHelp ご丁寧にありがとうございます。手続きさせていただきますが、二度と同じようなことがないように対策をお願い致します。 | C30: General / Feedback / Other | E30: ja | G30: active_troubleshooting | I30: false | K30: false | M30: standard | O30: Non-transactional social communication, conversational follow-up, or general inquiry. | P30: HIGH
A31: 230015 | B31: @AmazonHelp @115850 What's the status? Will I get a refund for this fake product or not? | C31: Returns, Replacements & Refunds | E31: en | G31: active_troubleshooting | I31: true | K31: false | M31: standard | O31: Customer demanding status update on refund promised for a fake product. | P31: HIGH | Q31: Could resemble Seller & Product Quality due to fake product, but primary actionable demand is refund status.
A32: 234555 | B32: What a discount, @115850. https://t.co/9rOKTidmrp | C32: Order & Checkout | E32: en | G32: new_issue | I32: false | K32: false | M32: standard | O32: Sarcastic screenshot highlighting erroneous or broken promotional discount calculation at checkout. | P32: HIGH | Q32: Could resemble General / Feedback / Other as sarcasm, but highlights checkout promo calculation bug.
A33: 246342 | B33: @AmazonHelp I am supposed to download Alexa, right? Is it available on the android store? | C33: Digital Services & Devices | E33: en | G33: active_troubleshooting | I33: false | K33: false | M33: standard | O33: Customer inquiring how and where to download the Alexa application on an Android device. | P33: HIGH
A34: 258713 | B34: @AmazonHelp Dear Amazon, please don't try to understand "my concern"! Please post my review to help ur innocent customers. #ScamAtAmazon #Day48 | C34: Seller & Product Quality | E34: en | G34: active_troubleshooting | I34: true | K34: false | M34: standard | O34: Customer demanding publication of rejected product review to warn other buyers against poor merchandise. | P34: HIGH | Q34: Could resemble General / Feedback / Other as venting, but specifically disputes product review moderation.
A35: 268666 | B35: @AmazonHelp My software on the Roku is up-to-date and I deleted and reinstalled the Amazon Video app. It still doesn’t work. The link is for LG&amp; Samsung | C35: Digital Services & Devices | E35: en | G35: active_troubleshooting | I35: true | K35: false | M35: standard | O35: Amazon Video application crashing/freezing on Roku device after update and reinstallation. | P35: HIGH
A36: 274703 | B36: @AmazonHelp I want to knw public how u treat customer issues.. | C36: General / Feedback / Other | E36: en | G36: active_troubleshooting | I36: false | K36: false | M36: standard | O36: Non-transactional social communication, conversational follow-up, or general inquiry. | P36: HIGH
A37: 275129 | B37: @115821 Please help! Someone hacked my account and I can’t contact you on your website as they changed the email and I cannot log in! | C37: Account Access & Security | E37: en | G37: new_issue | I37: true | K37: true | M37: P0_CRITICAL | O37: Customer account hacked with email address changed preventing user login; critical security intervention required. | P37: HIGH
A38: 279337 | B38: @AmazonHelp I have already responded, but that does not resolve my problem ... I just need my money back | C38: Returns, Replacements & Refunds | E38: en | G38: active_troubleshooting | I38: true | K38: false | M38: standard | O38: Customer stating that previous replies did not resolve the problem and demanding their money back. | P38: HIGH | Q38: Could resemble General / Feedback / Other as venting, but core demand is refund reimbursement.
A39: 279504 | B39: @AmazonHelp https://t.co/gprkxWgCzm | C39: General / Feedback / Other | E39: en | G39: active_troubleshooting | I39: false | K39: false | M39: standard | O39: Non-transactional social communication, conversational follow-up, or general inquiry. | P39: HIGH
A40: 284009 | B40: @AmazonHelp @115821 No card left, no phone call to advise they were here. Reception manned 100% of the time! | C40: Delivery Problem & Logistics | E40: en | G40: active_troubleshooting | I40: true | K40: false | M40: standard | O40: Courier falsely claimed delivery attempt without calling or leaving calling card despite manned reception. | P40: HIGH
A41: 291347 | B41: @AmazonHelp If you are unable to check in your back-end &amp; have no access to it, why bother to solve? Let @115850 turn bankrupt. Customer isn't imp 4 u | C41: General / Feedback / Other | E41: en | G41: active_troubleshooting | I41: false | K41: false | M41: standard | O41: Customer expressing general corporate dissatisfaction without actionable order parameters. | P41: HIGH
...

Sheet Taxonomy
A1: Intent Name | B1: Operational Scope & Definition | C1: Inclusion Criteria | D1: Exclusion Criteria | E1: Real Dataset Example | F1: Closest Competing Intent & Boundary Rule
A2: Delivery Tracking & Status | B2: Inquiries regarding package transit status, carrier information, or ETA while order is STILL WITHIN expected delivery SLA window. | C2: Asking tracking number, carrier name, ETA, dispatch timeline before SLA breach. | D2: Package overdue, delayed, marked delivered but missing, courier misconduct -> Delivery Problem & Logistics. | E2: @AmazonHelp the second item to be delivered today, maybe. Not updated tracking since Tuesday. Tracking useless | F2: Competing: Delivery Problem & Logistics. Rule: If package is overdue, missed date, or marked delivered but not received, it is Delivery Problem & Logistics.
A3: Delivery Problem & Logistics | B3: Escalations concerning a failure in the physical delivery, fulfillment, or doorstep handover of an order. | C3: Orders overdue, missed promised date/time, false delivery claims ('customer not home'), delivered but missing, crushed shipping boxes. | D3: Package in transit within SLA -> Delivery Tracking. Inquiring how to return damaged goods -> Returns. Defective product manufacturing -> Seller & Product Quality. | E3: @AmazonHelp Thanks. Expected 8 October. 9 October almost done and still not delivered. Contacting you for assistance not easy. | F3: Competing: Delivery Tracking & Status / Prime. Rule: If customer mentions Prime only regarding a late package ('I pay for Prime, why is it late?'), it is Delivery Problem & Logistics.
A4: Returns, Replacements & Refunds | B4: Requests or inquiries concerning returning an item, exchanging/replacing an item, obtaining return labels, or tracking return/cancellation refunds. | C4: Return process questions, replacement/exchange requests, return drop-off logistics, refund status for returned or cancelled orders. | D4: Unrecognized card charges -> Payment, Billing. General defect without return request -> Seller & Product Quality. Pre-dispatch cancellation -> Order & Checkout. | E4: @AmazonHelp very bad customer support i order a product and receive defective product and again apply for order refund but no response. | F4: Competing: Payment, Billing & Gift Cards. Rule: If money is owed as a result of a return, exchange, or order cancellation, classify under Returns, Replacements & Refunds.
A5: Payment, Billing & Gift Cards | B5: Inquiries and disputes regarding payment processing, unauthorized charges, double debits, gift cards, Amazon Pay balance, COD rules, and tax invoices. | C5: Double charges, unrecognized debit on bank statement, payment declined, gift card claim failure, Cash on Delivery disputes, official GST invoices. | D5: Refund owed from returned item -> Returns, Replacements & Refunds. Prime subscription auto-renew fee -> Prime. Account takeover fraud -> Account Access. | E5: @AmazonHelp I think I’ve been charged for my items individually rather than in one go. | F5: Competing: Returns, Replacements & Refunds. Rule: Charges originating from Amazon checkout, gift card balances, invoices, or COD belong here. Refunds from physical returns belong in Returns.
A6: Prime & Subscription Services | B6: Inquiries strictly concerning Amazon Prime membership contract, subscription fees, auto-renewal, student Prime, or subscription benefits (Prime Music, Kindle Unlimited). | C6: Prime sign-up, free trial terms, auto-renewal settings, cancellation requests, membership fees, Prime Student verification. | D6: Complaining that Prime package arrived late -> Delivery Problem & Logistics. Prime Video app crashing -> Digital Services. Returning Prime purchase -> Returns. | E6: Amazonプライム勝手に継続登録になって無駄にお金払ってから約半年... 来年もプライム会員継続しようかと心揺れてる (Auto-renewed Prime without realizing) | F6: Competing: Delivery Problem & Logistics. Rule: Use Prime & Subscription Services ONLY when the subject of inquiry is the membership contract itself. Late Prime deliveries belong in Delivery Problem.
A7: Order & Checkout | B7: Pre-fulfillment order management and purchasing issues: canceling prior to shipment, changing address before dispatch, promo codes failing, checkout errors. | C7: Canceling order before shipping, modifying delivery speed/address before fulfillment, promo codes/coupons failing at cart, lightning deal pricing glitches. | D7: Order already shipped and customer wants to track it -> Delivery Tracking. Order delivered and customer wants to return -> Returns. Card declined -> Payment. | E7: @AmazonHelp And secondly I would like to know if it was out of stock how I was able to place the order | F7: Competing: Returns, Replacements & Refunds. Rule: Pre-dispatch modifications or cart/deal issues belong to Order & Checkout. Post-dispatch cancellation belongs to Returns.
A8: Account Access & Security | B8: Inquiries regarding Amazon authentication, login credentials, two-factor authentication (2FA/OTP), locked accounts, and critical security issues (hacked account, phishing SMS). | C8: Unable to sign in, forgotten password, 2FA/OTP verification code not received, account suspended/locked, phishing emails/SMS, compromised credentials. | D8: Regular billing inquiry on active account -> Payment. Accessing specific Kindle eBook -> Digital Services. | E8: @115821 Please help! Someone hacked my account and I can’t contact you on your website as they changed the email and I cannot log in! | F8: Competing: Payment, Billing & Gift Cards. Rule: If the barrier prevents authentication or involves security/fraud/scams, classify under Account Access & Security with is_security_alert: true when malicious.
A9: Digital Services & Devices | B9: Technical support, device setup, and content delivery for Amazon hardware (Kindle, Echo/Alexa, Fire TV) and digital services (Prime Video streaming, Amazon Music, app crashes). | C9: Hardware setup/malfunction, Prime Video playback buffering/errors, Kindle eBook download failures, Amazon mobile app/website technical errors. | D9: Inquiries about Prime subscription pricing -> Prime & Subscription Services. Non-Amazon physical products defective -> Seller & Product Quality. | E9: @116618 glad I can watch Thursday night football with prime. But please address the quality and consistency with your streaming service when it comes to live football. | F9: Competing: Prime & Subscription Services. Rule: Technical glitches, streaming errors, app crashes, and Alexa/Kindle hardware issues belong here. Subscription contracts belong in Prime.
A10: Seller & Product Quality | B10: Grievances regarding physical product condition, manufacturing defects, counterfeit/fake items, 3rd-party marketplace seller unresponsiveness, or review rejections. | C10: Accusations of fake/counterfeit goods, defective items, broken merchandise, misleading product listings, 3rd-party seller disputes, product review moderation disputes. | D10: Product damaged solely because courier crushed outer shipping box -> Delivery Problem & Logistics. Customer explicitly requesting return label/refund -> Returns. | E10: @115850 I ordered dymatize whey protein and its fake.. it doesn’t taste like vanilla it has poor packaging.. customer care no. On hologram doesn’t work. | F10: Competing: Returns, Replacements & Refunds. Rule: If the customer is describing the defect, fake item, or seller grievance, classify under Seller & Product Quality. If demanding the return/refund process, classify under Returns.
A11: General / Feedback / Other | B11: Non-transactional communications, general feedback, customer appreciation, unspecific venting, conversational handshakes ('check DM'), and social media chatter. | C11: Customer praise/thanks, general venting without specific order details, conversational DM handshakes ('Sent DM', 'check inbox'), polite closings. | D11: Any message that articulates an actionable order, delivery, payment, account, or product issue -> Route to the specific business intent. | E11: @AmazonHelp Done, your customer service rep was most helpful! | F11: Competing: None (catch-all for non-actionable turns). Rule: Use General / Feedback / Other ONLY when there is no actionable transaction or specific problem matching classes 1-9.

Sheet Decision Rules
A1: Principle / Policy Area | B1: Core Operational Rule | C1: Implementation Standard & Examples
A2: 1. Separation of Concerns: Language | B2: LANGUAGE IS METADATA, NOT INTENT. | C2: Customer language is captured in 'language' ('en', 'es', 'ja', 'de', 'pt', 'fr', 'it', 'other'). Multilingual queries must be classified into their true underlying business intent.
A3: 2. Separation of Concerns: Conversation State | B3: CONVERSATION STATE IS DIALOGUE PHASE, NOT INTENT. | C3: Captured in 'conversation_state': 'new_issue' (opener), 'active_troubleshooting' (mid-thread diagnosis), 'dm_handoff' ('check DM'), 'follow_up' (providing requested details), 'resolved_or_acknowledgment' ('thanks/done'), 'unclear' (fragmentary).
A4: 3. Separation of Concerns: Escalation & Priority | B4: ESCALATION AND SECURITY ARE NOT SEPARATE ROUTING INTENTS. | C4: Fraud, phishing, and account takeover are classified under 'Account Access & Security' with orthogonal attributes 'is_security_alert: true' and 'priority: P0_CRITICAL'.
A5: 4. Escalation Decision Protocol | B5: SET ESCALATE=TRUE WHEN HUMAN AGENT INTERVENTION IS REQUIRED. | C5: Set true when: security/phishing threat exists, account compromise suspected, high-risk financial dispute, needs account/order-specific intervention that automated systems cannot execute, or customer is escalating. Set false when routine FAQ/guidance or standard tracking suffices.
A6: 5. Critical Boundary: Tracking vs Problem | B6: IN-TRANSIT SLA INTEGRITY GOVERNS ROUTING. | C6: If package is still within promised SLA delivery window without reported failure -> 'Delivery Tracking & Status'. If package is late, missed date/time, false attempt scan, or marked delivered but missing -> 'Delivery Problem & Logistics'.
A7: 6. Critical Boundary: Prime vs Delivery Problem | B7: THE CORE OBJECT OF INQUIRY GOVERNS ROUTING. | C7: If customer mentions Prime only to emphasize late delivery ('I pay for Prime, why is my delivery late?') -> 'Delivery Problem & Logistics'. Classify under 'Prime & Subscription Services' ONLY if the inquiry concerns subscription terms, fees, or cancellation.
A8: 7. Critical Boundary: Return vs Payment/Billing | B8: TRANSACTION ORIGIN GOVERNS REFUNDS. | C8: If money is owed resulting from a returned item, exchange, or cancelled order -> 'Returns, Replacements & Refunds'. If the dispute is about unexpected checkout debits, invoices, gift card balances, or COD -> 'Payment, Billing & Gift Cards'.
A9: 8. Critical Boundary: Product Quality vs Returns | B9: CUSTOMER'S PRIMARY ACTIONABLE DEMAND GOVERNS ROUTING. | C9: If message primarily details a defect, fake item, or seller grievance -> 'Seller & Product Quality'. If customer has moved past describing the defect and is explicitly requesting the return label or refund -> 'Returns, Replacements & Refunds'.

Sheet Difficult Cases
A1: message_id | B1: original_text | C1: proposed_intent | D1: alternative_intent | E1: ambiguity_rationale
A2: 1721 | B2: @AmazonHelp Never got the beta and now I’m being told I won’t get ANY of the other stuff. Including Last Jedi content and or bonus classes. Anything! :( | C2: General / Feedback / Other | D2: Order & Checkout or Digital Services & Devices, | E2: Could resemble Order & Checkout or Digital Services & Devices, but focuses on promotional extras.
A3: 25279 | B3: @AmazonHelp Yes I have contacted Amazon and this problem is going to cost me a lot of money and as of right now there is solution. | C3: General / Feedback / Other | D3: Alternative Category | E3: Could relate to multiple domains, but tweet contains no specific operational facts.
A4: 34485 | B4: @AmazonHelp Bonjour et merci. Un vendeur tiers qui ne répond pas et qui après enquête a tout l'air d'être un escroc. | C4: Seller & Product Quality | D4: Account Access & Security | E4: Could resemble Account Access & Security due to 'escroc' (scam), but problem is 3rd-party merchant conduct.
A5: 49143 | B5: @AmazonHelp Yes but it is a robot emails! I tried and mailed several emails with my bank statement and nothing happens. Hv other email for help me? | C5: Payment, Billing & Gift Cards | D5: Account Access & Security if bank statement is for ID verification, | E5: Could resemble Account Access & Security if bank statement is for ID verification, but involves payment proof.
A6: 57428 | B6: @AmazonHelp It say's "Could not set your address. Please ensure you have correctly entered a complete address" when I am entering my India address | C6: General / Feedback / Other | D6: Order & Checkout, | E6: Could resemble Order & Checkout, but represents address book entry error.
A7: 61025 | B7: So I change my country of residence &amp; I get charged again for prime services without mentioning that before?! #NotCool #UX 🤬 @116316 | C7: Prime & Subscription Services | D7: Payment, Billing & Gift Cards | E7: Could resemble Payment, Billing & Gift Cards due to unexpected charge, but contract issue is Prime subscription transfer.
A8: 95437 | B8: @AmazonHelp - It is really poor service or has your online chat support been hacked ? | C8: Account Access & Security | D8: General / Feedback / Other | E8: Could resemble General / Feedback / Other due to sarcastic frustration, but explicit inquiry about hacked chat warrants security review.
A9: 105253 | B9: @AmazonHelp Ich hatte vergessen zu erwähnen, dass es ein englisches ebook ist. Wie sieht es da mit der Vorbestellergarantie aus? | C9: Digital Services & Devices | D9: Order & Checkout | E9: Could resemble Order & Checkout due to pre-order guarantee, but digital eBook format specifics apply.
A10: 139986 | B10: Sympa, quand tu commande une Yankee candle sur @120533 et qu'elle arrive en mille morceaux 😠 | C10: Delivery Problem & Logistics | D10: Seller & Product Quality, | E10: Could resemble Seller & Product Quality, but shatter damage during transit is a delivery logistics failure.
A11: 142048 | B11: @AmazonHelp hey, on another note, two of my recent purchases which i asked for a return, havent been picked up yet. it's been more than two weeks. | C11: Returns, Replacements & Refunds | D11: Delivery Problem & Logistics | E11: Could resemble Delivery Problem & Logistics due to courier delay, but operation is return reverse-logistics.
A12: 142870 | B12: @AmazonHelp Tell you what I will ask is how come prime is no longer next day delivery? I’ve ordered loads of things lately over the last month and they’ve taken ages to be delivered? | C12: Delivery Problem & Logistics | D12: Alternative Category | E12: Mentions Prime, but under taxonomy rules late delivery complaints belong to Delivery Problem & Logistics.
A13: 162100 | B13: @AmazonHelp Ja. Komm nicht an der Info vorbei. Bei einem anderen Spiel lief es problemlos | C13: Digital Services & Devices | D13: Order & Checkout as software purchase, | E13: Could resemble Order & Checkout as software purchase, but is an in-game technical bug.
... A31: 754571 | B31: @115850 Unhappy with my last order, delayed Delivery and Single sim phone instead of dual sim delivered. | C31: Delivery Problem & Logistics | D31: Seller & Product Quality | E31: Could resemble Seller & Product Quality due to single-sim delivered, but delayed delivery is combined.

Sheet Agreement Analysis
A1: ASSISTANT VS HUMAN ANNOTATION AGREEMENT ANALYSIS
A2: NOTE: These are annotation-assistance agreement statistics measuring alignment between assistant proposals and human gold labels. They do NOT represent AI customer-support agent model evaluation accuracy.
A4: Evaluation Dimension | B4: Assistant Proposed Field | C4: Human Gold Field | D4: Completed Reviews | E4: Matching Agreements | F4: Agreement Rate
A5: Intent Classification | B5: C6:C205 | C5: D6:D205 | D5: =COUNTA(Review!D6:D205) | E5: =IF(COUNTA(Review!D6:D205)=0, 0, SUMPRODUCT(--(Review!C6:C205=Review!D6:D205))) | F5: =IF(COUNTA(Review!D6:D205)=0, "Pending Review", SUMPRODUCT(--(Review!C6:C205=Review!D6:D205))/COUNTA(Review!D6:D205))
A6: Language Detection | B6: E6:E205 | C6: F6:F205 | D6: =COUNTA(Review!F6:F205) | E6: =IF(COUNTA(Review!F6:F205)=0, 0, SUMPRODUCT(--(Review!E6:E205=Review!F6:F205))) | F6: =IF(COUNTA(Review!F6:F205)=0, "Pending Review", SUMPRODUCT(--(Review!E6:E205=Review!F6:F205))/COUNTA(Review!F6:F205))
A7: Conversation State | B7: G6:G205 | C7: H6:H205 | D7: =COUNTA(Review!H6:H205) | E7: =IF(COUNTA(Review!H6:H205)=0, 0, SUMPRODUCT(--(Review!G6:G205=Review!H6:H205))) | F7: =IF(COUNTA(Review!H6:H205)=0, "Pending Review", SUMPRODUCT(--(Review!G6:G205=Review!H6:H205))/COUNTA(Review!H6:H205))
A8: Escalation Routing | B8: I6:I205 | C8: J6:J205 | D8: =COUNTA(Review!J6:J205) | E8: =IF(COUNTA(Review!J6:J205)=0, 0, SUMPRODUCT(--(Review!I6:I205=Review!J6:J205))) | F8: =IF(COUNTA(Review!J6:J205)=0, "Pending Review", SUMPRODUCT(--(Review!I6:I205=Review!J6:J205))/COUNTA(Review!J6:J205))
A9: Security Alert Flag | B9: K6:K205 | C9: L6:L205 | D9: =COUNTA(Review!L6:L205) | E9: =IF(COUNTA(Review!L6:L205)=0, 0, SUMPRODUCT(--(Review!K6:K205=Review!L6:L205))) | F9: =IF(COUNTA(Review!L6:L205)=0, "Pending Review", SUMPRODUCT(--(Review!K6:K205=Review!L6:L205))/COUNTA(Review!L6:L205))
A10: Escalation Priority | B10: M6:M205 | C10: N6:N205 | D10: =COUNTA(Review!N6:N205) | E10: =IF(COUNTA(Review!N6:N205)=0, 0, SUMPRODUCT(--(Review!M6:M205=Review!N6:N205))) | F10: =IF(COUNTA(Review!N6:N205)=0, "Pending Review", SUMPRODUCT(--(Review!M6:M205=Review!N6:N205))/COUNTA(Review!N6:N205))
